<robot name="sassa">
<link name="body_sasm">
<visual>
<origin xyz="-2.498001805406602216e-16 6.9388939039072283776e-18 1.8041124150158793782e-16" rpy="-9.7843404150693598069e-29 7.888609052210114691e-29 -1.570796326794896558" />
<geometry>
<mesh filename="package:///handle.stl"/>
</geometry>
<material name="handle_material">
<color rgba="1 0 0 1.0"/>
</material>
</visual>
<collision>
<origin xyz="-2.498001805406602216e-16 6.9388939039072283776e-18 1.8041124150158793782e-16" rpy="-9.7843404150693598069e-29 7.888609052210114691e-29 -1.570796326794896558" />
<geometry>
<mesh filename="package:///handle.stl"/>
</geometry>
</collision>
<visual>
<origin xyz="-0.12800000000000033573 1.0408340855861448079e-17 -1.9428902930940239457e-16" rpy="-1.570796326794896558 7.888609052210114691e-29 -1.570796326794896558" />
<geometry>
<mesh filename="package:///body_panel.stl"/>
</geometry>
<material name="body_panel_material">
<color rgba="1 0 0 1.0"/>
</material>
</visual>
<collision>
<origin xyz="-0.12800000000000033573 1.0408340855861448079e-17 -1.9428902930940239457e-16" rpy="-1.570796326794896558 7.888609052210114691e-29 -1.570796326794896558" />
<geometry>
<mesh filename="package:///body_panel.stl"/>
</geometry>
</collision>
<visual>
<origin xyz="0.12800000000000044675 0.060000000000000004718 5.5511151231257827021e-17" rpy="-1.570796326794896558 7.888609052210114691e-29 -1.570796326794896558" />
<geometry>
<mesh filename="package:///rmdx8v3.stl"/>
</geometry>
<material name="rmdx8v3_material">
<color rgba="0.26274509803921569651 0.28235294117647058432 0.30196078431372547213 1.0"/>
</material>
</visual>
<collision>
<origin xyz="0.12800000000000044675 0.060000000000000004718 5.5511151231257827021e-17" rpy="-1.570796326794896558 7.888609052210114691e-29 -1.570796326794896558" />
<geometry>
<mesh filename="package:///rmdx8v3.stl"/>
</geometry>
</collision>
<visual>
<origin xyz="-0.12800000000000033573 0.060000000000000011657 -1.9428902930940239457e-16" rpy="1.570796326794896558 7.888609052210114691e-29 -1.570796326794896558" />
<geometry>
<mesh filename="package:///rmdx8v3.stl"/>
</geometry>
<material name="rmdx8v3_material">
<color rgba="0.26274509803921569651 0.28235294117647058432 0.30196078431372547213 1.0"/>
</material>
</visual>
<collision>
<origin xyz="-0.12800000000000033573 0.060000000000000011657 -1.9428902930940239457e-16" rpy="1.570796326794896558 7.888609052210114691e-29 -1.570796326794896558" />
<geometry>
<mesh filename="package:///rmdx8v3.stl"/>
</geometry>
</collision>
<visual>
<origin xyz="0 0 0" rpy="1.8669045833583375598e-58 7.8886090522101281435e-29 -1.570796326794896558" />
<geometry>
<mesh filename="package:///body.stl"/>
</geometry>
<material name="body_material">
<color rgba="0.2745098039215686514 0.2745098039215686514 0.2745098039215686514 1.0"/>
</material>
</visual>
<collision>
<origin xyz="0 0 0" rpy="1.8669045833583375598e-58 7.8886090522101281435e-29 -1.570796326794896558" />
<geometry>
<mesh filename="package:///body.stl"/>
</geometry>
</collision>
<visual>
<origin xyz="0.12800000000000044675 1.0408340855860438892e-17 5.5511151231257827021e-17" rpy="1.570796326794896558 7.888609052210114691e-29 -1.570796326794896558" />
<geometry>
<mesh filename="package:///body_panel.stl"/>
</geometry>
<material name="body_panel_material">
<color rgba="1 0 0 1.0"/>
</material>
</visual>
<collision>
<origin xyz="0.12800000000000044675 1.0408340855860438892e-17 5.5511151231257827021e-17" rpy="1.570796326794896558 7.888609052210114691e-29 -1.570796326794896558" />
<geometry>
<mesh filename="package:///body_panel.stl"/>
</geometry>
</collision>
<visual>
<origin xyz="0.12800000000000044675 -0.059999999999999990841 5.5511151231257827021e-17" rpy="-1.570796326794896558 7.888609052210114691e-29 -1.570796326794896558" />
<geometry>
<mesh filename="package:///rmdx8v3.stl"/>
</geometry>
<material name="rmdx8v3_material">
<color rgba="0.26274509803921569651 0.28235294117647058432 0.30196078431372547213 1.0"/>
</material>
</visual>
<collision>
<origin xyz="0.12800000000000044675 -0.059999999999999990841 5.5511151231257827021e-17" rpy="-1.570796326794896558 7.888609052210114691e-29 -1.570796326794896558" />
<geometry>
<mesh filename="package:///rmdx8v3.stl"/>
</geometry>
</collision>
<visual>
<origin xyz="-0.12800000000000033573 -0.059999999999999983902 -1.9428902930940239457e-16" rpy="1.570796326794896558 7.888609052210114691e-29 -1.570796326794896558" />
<geometry>
<mesh filename="package:///rmdx8v3.stl"/>
</geometry>
<material name="rmdx8v3_material">
<color rgba="0.26274509803921569651 0.28235294117647058432 0.30196078431372547213 1.0"/>
</material>
</visual>
<collision>
<origin xyz="-0.12800000000000033573 -0.059999999999999983902 -1.9428902930940239457e-16" rpy="1.570796326794896558 7.888609052210114691e-29 -1.570796326794896558" />
<geometry>
<mesh filename="package:///rmdx8v3.stl"/>
</geometry>
</collision>
<inertial>
<origin xyz="1.0549119014210002315e-08 2.6420442197386651047e-06 0.0012678260149069624924" rpy="0 0 0"/>
<mass value="3.4790000000000000924" />
<inertia ixx="0.017238756351439742803" ixy="-1.0858624503035096964e-09"  ixz="-5.3345333846338443867e-05" iyy="0.06201091917991622543" iyz="-5.6946189178596202636e-07" izz="0.073697337716442989919" />
</inertial>
</link>

<link name="helbow_sasm">
<visual>
<origin xyz="-3.1225022567582527699e-17 -0.016999999999999994282 -0.05999999999999999778" rpy="1.570796326794896558 -6.5617017863841870815e-34 6.5617017838168550278e-34" />
<geometry>
<mesh filename="package:///angle_motor_connect.stl"/>
</geometry>
<material name="angle_motor_connect_material">
<color rgba="1 0 0 1.0"/>
</material>
</visual>
<collision>
<origin xyz="-3.1225022567582527699e-17 -0.016999999999999994282 -0.05999999999999999778" rpy="1.570796326794896558 -6.5617017863841870815e-34 6.5617017838168550278e-34" />
<geometry>
<mesh filename="package:///angle_motor_connect.stl"/>
</geometry>
</collision>
<visual>
<origin xyz="-3.1225022567582527699e-17 -0.016999999999999994282 -0.05999999999999999778" rpy="1.570796326794896558 0.3141592653589793116 -3.141592653589793116" />
<geometry>
<mesh filename="package:///rmdx8v3.stl"/>
</geometry>
<material name="rmdx8v3_material">
<color rgba="0.26274509803921569651 0.28235294117647058432 0.30196078431372547213 1.0"/>
</material>
</visual>
<collision>
<origin xyz="-3.1225022567582527699e-17 -0.016999999999999994282 -0.05999999999999999778" rpy="1.570796326794896558 0.3141592653589793116 -3.141592653589793116" />
<geometry>
<mesh filename="package:///rmdx8v3.stl"/>
</geometry>
</collision>
<inertial>
<origin xyz="5.944480483317752254e-05 -0.0057855661598585949104 -0.054844450125644705896" rpy="0 0 0"/>
<mass value="0.76500000000000001332" />
<inertia ixx="0.00070529619085715202723" ixy="8.1991517066850037332e-07"  ixz="-1.1586194990785575583e-06" iyy="0.0010092480556627564381" iyz="9.9300977410698304266e-06" izz="0.00061029448812635394769" />
</inertial>
</link>

<link name="upperleg_sasm">
<visual>
<origin xyz="4.5794955934427937194e-18 0 -0.079000000000000014655" rpy="1.5707963267948970021 2.9044849690249756194e-16 1.570796326794896558" />
<geometry>
<mesh filename="package:///61804-2rs.stl"/>
</geometry>
<material name="61804-2rs_material">
<color rgba="0.61568627450980395466 0.81176470588235294379 0.92941176470588238168 1.0"/>
</material>
</visual>
<collision>
<origin xyz="4.5794955934427937194e-18 0 -0.079000000000000014655" rpy="1.5707963267948970021 2.9044849690249756194e-16 1.570796326794896558" />
<geometry>
<mesh filename="package:///61804-2rs.stl"/>
</geometry>
</collision>
<visual>
<origin xyz="1.753469930634033528e-16 0 -0.053500000000000075273" rpy="3.141592653589793116 1.0047893711214148772e-16 1.6578076876195083607e-29" />
<geometry>
<mesh filename="package:///upperleg_cover.stl"/>
</geometry>
<material name="upperleg_cover_material">
<color rgba="1 0 0 1.0"/>
</material>
</visual>
<collision>
<origin xyz="1.753469930634033528e-16 0 -0.053500000000000075273" rpy="3.141592653589793116 1.0047893711214148772e-16 1.6578076876195083607e-29" />
<geometry>
<mesh filename="package:///upperleg_cover.stl"/>
</geometry>
</collision>
<visual>
<origin xyz="-3.0814879110195773649e-33 0 -0.023000000000000020428" rpy="1.570796326794896558 -0 0" />
<geometry>
<mesh filename="package:///inline_connect.stl"/>
</geometry>
<material name="inline_connect_material">
<color rgba="1 0 0 1.0"/>
</material>
</visual>
<collision>
<origin xyz="-3.0814879110195773649e-33 0 -0.023000000000000020428" rpy="1.570796326794896558 -0 0" />
<geometry>
<mesh filename="package:///inline_connect.stl"/>
</geometry>
</collision>
<visual>
<origin xyz="8.3984370386311552134e-18 0 -0.056000000000000021982" rpy="-3.141592653589793116 6.8403891977347234462e-17 1.570796326794896558" />
<geometry>
<mesh filename="package:///motor_pulley.stl"/>
</geometry>
<material name="motor_pulley_material">
<color rgba="1 0 0 1.0"/>
</material>
</visual>
<collision>
<origin xyz="8.3984370386311552134e-18 0 -0.056000000000000021982" rpy="-3.141592653589793116 6.8403891977347234462e-17 1.570796326794896558" />
<geometry>
<mesh filename="package:///motor_pulley.stl"/>
</geometry>
</collision>
<visual>
<origin xyz="1.3877787807814456755e-17 0 -0.02300000000000000655" rpy="-3.141592653589793116 6.8403891977347234462e-17 1.570796326794896558" />
<geometry>
<mesh filename="package:///rmdx8v3.stl"/>
</geometry>
<material name="rmdx8v3_material">
<color rgba="0.26274509803921569651 0.28235294117647058432 0.30196078431372547213 1.0"/>
</material>
</visual>
<collision>
<origin xyz="1.3877787807814456755e-17 0 -0.02300000000000000655" rpy="-3.141592653589793116 6.8403891977347234462e-17 1.570796326794896558" />
<geometry>
<mesh filename="package:///rmdx8v3.stl"/>
</geometry>
</collision>
<visual>
<origin xyz="3.6569114985258803736e-17 0 -0.053500000000000019762" rpy="-3.1415926535897926719 3.4480744915607654605e-16 1.6566079009641247914e-29" />
<geometry>
<mesh filename="package:///upperleg_main.stl"/>
</geometry>
<material name="upperleg_main_material">
<color rgba="1 0 0 1.0"/>
</material>
</visual>
<collision>
<origin xyz="3.6569114985258803736e-17 0 -0.053500000000000019762" rpy="-3.1415926535897926719 3.4480744915607654605e-16 1.6566079009641247914e-29" />
<geometry>
<mesh filename="package:///upperleg_main.stl"/>
</geometry>
</collision>
<inertial>
<origin xyz="0.015167598538525770002 -1.5067296714423377747e-07 -0.041111839365210615937" rpy="0 0 0"/>
<mass value="0.90300000000000013589" />
<inertia ixx="0.00079492894334647393705" ixy="2.0274701385558070391e-08"  ixz="0.00039814748290456752466" iyy="0.0027036181954660119461" iyz="-3.6423891445825261724e-09" izz="0.0028329445625492818972" />
</inertial>
</link>

<link name="lowerleg_sasm">
<visual>
<origin xyz="2.7755575615628913511e-17 0 -2.7755575615628913511e-17" rpy="2.9330896303248668082e-32 5.2919806624416397802e-31 -8.9902534028177188512e-32" />
<geometry>
<mesh filename="package:///lower_leg.stl"/>
</geometry>
<material name="lower_leg_material">
<color rgba="1 0 0 1.0"/>
</material>
</visual>
<collision>
<origin xyz="2.7755575615628913511e-17 0 -2.7755575615628913511e-17" rpy="2.9330896303248668082e-32 5.2919806624416397802e-31 -8.9902534028177188512e-32" />
<geometry>
<mesh filename="package:///lower_leg.stl"/>
</geometry>
</collision>
<visual>
<origin xyz="2.7755575615628913511e-17 0 -0.0060000000000000330846" rpy="-1.5707963267948992225 1.5694156464006572129e-15 1.0330794565568739415e-30" />
<geometry>
<mesh filename="package:///61804-2rs.stl"/>
</geometry>
<material name="61804-2rs_material">
<color rgba="0.61568627450980395466 0.81176470588235294379 0.92941176470588238168 1.0"/>
</material>
</visual>
<collision>
<origin xyz="2.7755575615628913511e-17 0 -0.0060000000000000330846" rpy="-1.5707963267948992225 1.5694156464006572129e-15 1.0330794565568739415e-30" />
<geometry>
<mesh filename="package:///61804-2rs.stl"/>
</geometry>
</collision>
<visual>
<origin xyz="2.7755575615628913511e-17 0 0.0060000000000000608402" rpy="1.5707963267949018871 3.2630587779497501504e-15 3.4947918559641619179e-31" />
<geometry>
<mesh filename="package:///61804-2rs.stl"/>
</geometry>
<material name="61804-2rs_material">
<color rgba="0.61568627450980395466 0.81176470588235294379 0.92941176470588238168 1.0"/>
</material>
</visual>
<collision>
<origin xyz="2.7755575615628913511e-17 0 0.0060000000000000608402" rpy="1.5707963267949018871 3.2630587779497501504e-15 3.4947918559641619179e-31" />
<geometry>
<mesh filename="package:///61804-2rs.stl"/>
</geometry>
</collision>
<visual>
<origin xyz="-1.415534356397074589e-15 0 3.0531133177191804862e-16" rpy="-2.5827259566927633692e-15 1.5694156464006621433e-15 1.0330794565568739415e-30" />
<geometry>
<mesh filename="package:///foot_ball.stl"/>
</geometry>
<material name="foot_ball_material">
<color rgba="0.26274509803921569651 0.28235294117647058432 0.30196078431372547213 1.0"/>
</material>
</visual>
<collision>
<origin xyz="-1.415534356397074589e-15 0 3.0531133177191804862e-16" rpy="-2.5827259566927633692e-15 1.5694156464006621433e-15 1.0330794565568739415e-30" />
<geometry>
<mesh filename="package:///foot_ball.stl"/>
</geometry>
</collision>
<inertial>
<origin xyz="0.092866734428134853352 3.4061659242104974425e-09 -1.3731468403229029231e-09" rpy="0 0 0"/>
<mass value="0.13200000000000006173" />
<inertia ixx="1.7231392269124719361e-05" ixy="2.7776605562875738498e-11"  ixz="-1.1254075299648235141e-11" iyy="0.00097781315953662188006" iyz="-2.3904249452672315351e-11" izz="0.00098262259218384780113" />
</inertial>
</link>

<link name="FL_foot">
<inertial>
<origin xyz="0 0 0" rpy="0 0 0" />
<mass value="1e-9" />
<inertia ixx="0" ixy="0" ixz="0" iyy="0" iyz="0" izz="0" />
</inertial>
</link>
<joint name="FL_foot_frame" type="fixed">
<origin xyz="0.21732050807564642914 -2.7339241981394479808e-14 -2.7755575615628913511e-17" rpy="-1.5707963267948950037 2.5827259566927519308e-15 1.570796326794896558" />
<parent link="lowerleg_sasm" />
<child link="FL_foot" />
<axis xyz="0 0 0"/>
</joint>

<joint name="FL2" type="revolute">
<origin xyz="0.21300000000000002265 6.4392935428259079345e-15 -0.068500000000000116351" rpy="5.3799142389700426073e-16 -2.219643924176522297e-15 -1.160061430643682592e-15" />
<parent link="upperleg_sasm" />
<child link="lowerleg_sasm" />
<axis xyz="0 0 1"/>
<limit effort="9" velocity="20" lower="-2.356194490192344837" upper="2.356194490192344837"/>
<joint_properties friction="0.0"/>
</joint>

<joint name="FL1" type="revolute">
<origin xyz="-2.1926730353241371394e-17 0.016000000000000007272 -0.05999999999999999778" rpy="-1.570796326794896558 -1.4025207337730963138e-27 -3.141592653589793116" />
<parent link="helbow_sasm" />
<child link="upperleg_sasm" />
<axis xyz="0 0 1"/>
<limit effort="9" velocity="20" lower="-1.570796326794896558" upper="1.570796326794896558"/>
<joint_properties friction="0.0"/>
</joint>

<joint name="FL0" type="revolute">
<origin xyz="0.16100000000000047606 0.060000000000000004718 6.00732341963438899e-17" rpy="-3.1278740296522731543e-30 -1.570796326794896336 0" />
<parent link="body_sasm" />
<child link="helbow_sasm" />
<axis xyz="0 0 1"/>
<limit effort="9" velocity="20" lower="-0.785398163397448279" upper="0.785398163397448279"/>
<joint_properties friction="0.0"/>
</joint>

<link name="helbow_sasm_2">
<visual>
<origin xyz="-3.1225022567582515373e-17 -0.016999999999999994282 -0.05999999999999999778" rpy="1.570796326794896558 -1.2304096749537510425e-32 2.1854894444503555251e-35" />
<geometry>
<mesh filename="package:///angle_motor_connect.stl"/>
</geometry>
<material name="angle_motor_connect_material">
<color rgba="1 0 0 1.0"/>
</material>
</visual>
<collision>
<origin xyz="-3.1225022567582515373e-17 -0.016999999999999994282 -0.05999999999999999778" rpy="1.570796326794896558 -1.2304096749537510425e-32 2.1854894444503555251e-35" />
<geometry>
<mesh filename="package:///angle_motor_connect.stl"/>
</geometry>
</collision>
<visual>
<origin xyz="-3.1225022567582515373e-17 -0.016999999999999994282 -0.05999999999999999778" rpy="1.57079632679489678 0.31415926535897942262 3.141592653589793116" />
<geometry>
<mesh filename="package:///rmdx8v3.stl"/>
</geometry>
<material name="rmdx8v3_material">
<color rgba="0.26274509803921569651 0.28235294117647058432 0.30196078431372547213 1.0"/>
</material>
</visual>
<collision>
<origin xyz="-3.1225022567582515373e-17 -0.016999999999999994282 -0.05999999999999999778" rpy="1.57079632679489678 0.31415926535897942262 3.141592653589793116" />
<geometry>
<mesh filename="package:///rmdx8v3.stl"/>
</geometry>
</collision>
<inertial>
<origin xyz="5.9444804833174412235e-05 -0.0057855661598585957778 -0.054844450125644705896" rpy="0 0 0"/>
<mass value="0.76500000000000001332" />
<inertia ixx="0.00070529619085715170197" ixy="8.1991517066816251306e-07"  ixz="-1.1586194990784332562e-06" iyy="0.0010092480556627564381" iyz="9.930097741069608504e-06" izz="0.00061029448812635351401" />
</inertial>
</link>

<link name="upperleg_sasm_2">
<visual>
<origin xyz="6.1629758220391547298e-33 -2.7755575615628913511e-17 0.02300000000000000655" rpy="-1.570796326794896558 -0 0" />
<geometry>
<mesh filename="package:///inline_connect.stl"/>
</geometry>
<material name="inline_connect_material">
<color rgba="1 0 0 1.0"/>
</material>
</visual>
<collision>
<origin xyz="6.1629758220391547298e-33 -2.7755575615628913511e-17 0.02300000000000000655" rpy="-1.570796326794896558 -0 0" />
<geometry>
<mesh filename="package:///inline_connect.stl"/>
</geometry>
</collision>
<visual>
<origin xyz="6.4336349891566550057e-17 -6.1062266354383609723e-16 0.079000000000000139555" rpy="-1.5707963267948961139 6.7027630163414756467e-15 -1.570796326794896558" />
<geometry>
<mesh filename="package:///61804-2rs.stl"/>
</geometry>
<material name="61804-2rs_material">
<color rgba="0.61568627450980395466 0.81176470588235294379 0.92941176470588238168 1.0"/>
</material>
</visual>
<collision>
<origin xyz="6.4336349891566550057e-17 -6.1062266354383609723e-16 0.079000000000000139555" rpy="-1.5707963267948961139 6.7027630163414756467e-15 -1.570796326794896558" />
<geometry>
<mesh filename="package:///61804-2rs.stl"/>
</geometry>
</collision>
<visual>
<origin xyz="6.3189891121763626325e-17 -6.1062266354383609723e-16 0.05600000000000003586" rpy="5.680172150174810756e-16 6.7027630163414598695e-15 -1.570796326794896558" />
<geometry>
<mesh filename="package:///motor_pulley.stl"/>
</geometry>
<material name="motor_pulley_material">
<color rgba="1 0 0 1.0"/>
</material>
</visual>
<collision>
<origin xyz="6.3189891121763626325e-17 -6.1062266354383609723e-16 0.05600000000000003586" rpy="5.680172150174810756e-16 6.7027630163414598695e-15 -1.570796326794896558" />
<geometry>
<mesh filename="package:///motor_pulley.stl"/>
</geometry>
</collision>
<visual>
<origin xyz="-1.3123441721320433052e-15 -4.4408920985006261617e-16 0.053500000000000005884" rpy="6.7027630163415332335e-15 -5.6801721501752919612e-16 7.1453259975484494892e-15" />
<geometry>
<mesh filename="package:///upperleg_cover.stl"/>
</geometry>
<material name="upperleg_cover_material">
<color rgba="1 0 0 1.0"/>
</material>
</visual>
<collision>
<origin xyz="-1.3123441721320433052e-15 -4.4408920985006261617e-16 0.053500000000000005884" rpy="6.7027630163415332335e-15 -5.6801721501752919612e-16 7.1453259975484494892e-15" />
<geometry>
<mesh filename="package:///upperleg_cover.stl"/>
</geometry>
</collision>
<visual>
<origin xyz="1.0468797551964143432e-15 -4.4408920985006261617e-16 0.053500000000000005884" rpy="6.5917407138790278347e-15 -5.6801721501755887701e-16 7.1453259975484510669e-15" />
<geometry>
<mesh filename="package:///upperleg_main.stl"/>
</geometry>
<material name="upperleg_main_material">
<color rgba="1 0 0 1.0"/>
</material>
</visual>
<collision>
<origin xyz="1.0468797551964143432e-15 -4.4408920985006261617e-16 0.053500000000000005884" rpy="6.5917407138790278347e-15 -5.6801721501755887701e-16 7.1453259975484510669e-15" />
<geometry>
<mesh filename="package:///upperleg_main.stl"/>
</geometry>
</collision>
<visual>
<origin xyz="5.5511151231257537361e-17 -6.1062266354383609723e-16 0.022999999999999895528" rpy="5.6801721501720635479e-16 6.7027630163414614472e-15 -1.570796326794896558" />
<geometry>
<mesh filename="package:///rmdx8v3.stl"/>
</geometry>
<material name="rmdx8v3_material">
<color rgba="0.26274509803921569651 0.28235294117647058432 0.30196078431372547213 1.0"/>
</material>
</visual>
<collision>
<origin xyz="5.5511151231257537361e-17 -6.1062266354383609723e-16 0.022999999999999895528" rpy="5.6801721501720635479e-16 6.7027630163414614472e-15 -1.570796326794896558" />
<geometry>
<mesh filename="package:///rmdx8v3.stl"/>
</geometry>
</collision>
<inertial>
<origin xyz="0.015167598538526300828 1.5067296670218930515e-07 0.041111839365210588182" rpy="0 0 0"/>
<mass value="0.90300000000000002487" />
<inertia ixx="0.00079492894334647805701" ixy="-2.0274701384702897987e-08"  ixz="-0.00039814748290457999298" iyy="0.0027036181954661203664" iyz="-3.6423891380999543117e-09" izz="0.0028329445625493547556" />
</inertial>
</link>

<link name="lowerleg_sasm_2">
<visual>
<origin xyz="0 0 -0.0059999999999999775735" rpy="-1.5707963267948974462 -2.8921564122512183152e-16 -2.5429977452726976378e-30" />
<geometry>
<mesh filename="package:///61804-2rs.stl"/>
</geometry>
<material name="61804-2rs_material">
<color rgba="0.61568627450980395466 0.81176470588235294379 0.92941176470588238168 1.0"/>
</material>
</visual>
<collision>
<origin xyz="0 0 -0.0059999999999999775735" rpy="-1.5707963267948974462 -2.8921564122512183152e-16 -2.5429977452726976378e-30" />
<geometry>
<mesh filename="package:///61804-2rs.stl"/>
</geometry>
</collision>
<visual>
<origin xyz="9.4924068605450884206e-15 0 -5.5511151231257827021e-17" rpy="-8.9544612897452844334e-16 -2.8921564122512183152e-16 -2.5429977452726976378e-30" />
<geometry>
<mesh filename="package:///foot_ball.stl"/>
</geometry>
<material name="foot_ball_material">
<color rgba="0.26274509803921569651 0.28235294117647058432 0.30196078431372547213 1.0"/>
</material>
</visual>
<collision>
<origin xyz="9.4924068605450884206e-15 0 -5.5511151231257827021e-17" rpy="-8.9544612897452844334e-16 -2.8921564122512183152e-16 -2.5429977452726976378e-30" />
<geometry>
<mesh filename="package:///foot_ball.stl"/>
</geometry>
</collision>
<visual>
<origin xyz="0 0 0" rpy="-5.1000508100181411593e-33 2.3072833772312297433e-32 -9.0053785238347150527e-32" />
<geometry>
<mesh filename="package:///lower_leg.stl"/>
</geometry>
<material name="lower_leg_material">
<color rgba="1 0 0 1.0"/>
</material>
</visual>
<collision>
<origin xyz="0 0 0" rpy="-5.1000508100181411593e-33 2.3072833772312297433e-32 -9.0053785238347150527e-32" />
<geometry>
<mesh filename="package:///lower_leg.stl"/>
</geometry>
</collision>
<visual>
<origin xyz="0 0 0.0059999999999999498179" rpy="1.5707963267948954478 -4.0133753269177027904e-31 6.9098931621081517189e-31" />
<geometry>
<mesh filename="package:///61804-2rs.stl"/>
</geometry>
<material name="61804-2rs_material">
<color rgba="0.61568627450980395466 0.81176470588235294379 0.92941176470588238168 1.0"/>
</material>
</visual>
<collision>
<origin xyz="0 0 0.0059999999999999498179" rpy="1.5707963267948954478 -4.0133753269177027904e-31 6.9098931621081517189e-31" />
<geometry>
<mesh filename="package:///61804-2rs.stl"/>
</geometry>
</collision>
<inertial>
<origin xyz="0.092866734428134797841 3.4061659242104978561e-09 -1.3731468248172282193e-09" rpy="0 0 0"/>
<mass value="0.13200000000000006173" />
<inertia ixx="1.7231392269123957031e-05" ixy="2.7776605499672273454e-11"  ixz="-1.1254075513365238877e-11" iyy="0.00097781315953662079586" iyz="-2.3904249463132311465e-11" izz="0.00098262259218384693377" />
</inertial>
</link>

<link name="FR_foot">
<inertial>
<origin xyz="0 0 0" rpy="0 0 0" />
<mass value="1e-9" />
<inertia ixx="0" ixy="0" ixz="0" iyy="0" iyz="0" izz="0" />
</inertial>
</link>
<joint name="FR_foot_frame" type="fixed">
<origin xyz="0.21732050807564631811 -2.7311486405778850894e-14 0" rpy="-1.5707963267948970021 8.9544612897454717878e-16 1.5707963267949038855" />
<parent link="lowerleg_sasm_2" />
<child link="FR_foot" />
<axis xyz="0 0 0"/>
</joint>

<joint name="FR2" type="revolute">
<origin xyz="0.21300000000000654521 -5.3568260938163803075e-15 0.06850000000000018574" rpy="6.9248076212676153043e-15 -7.9006181994192093522e-16 9.0032171146696425232e-15" />
<parent link="upperleg_sasm_2" />
<child link="lowerleg_sasm_2" />
<axis xyz="0 0 1"/>
<limit effort="9" velocity="20" lower="-2.356194490192344837" upper="2.356194490192344837"/>
<joint_properties friction="0.0"/>
</joint>

<joint name="FR1" type="revolute">
<origin xyz="-4.2430336288061214674e-17 0.015999999999999993394 -0.05999999999999999778" rpy="-1.57079632679489678 -1.8467845446348508561e-15 3.896800864265682098e-17" />
<parent link="helbow_sasm_2" />
<child link="upperleg_sasm_2" />
<axis xyz="0 0 1"/>
<limit effort="9" velocity="20" lower="-1.570796326794896558" upper="1.570796326794896558"/>
<joint_properties friction="0.0"/>
</joint>

<joint name="FR0" type="revolute">
<origin xyz="0.16100000000000047606 -0.059999999999999990841 5.6159486713100279927e-17" rpy="-3.141592653589793116 1.570796326794896336 0" />
<parent link="body_sasm" />
<child link="helbow_sasm_2" />
<axis xyz="0 0 1"/>
<limit effort="9" velocity="20" lower="-0.785398163397448279" upper="0.785398163397448279"/>
<joint_properties friction="0.0"/>
</joint>

<link name="helbow_sasm_3">
<visual>
<origin xyz="-3.1225022567582527699e-17 -0.016999999999999994282 -0.05999999999999999778" rpy="1.570796326794896558 0.3141592653589793116 -3.141592653589793116" />
<geometry>
<mesh filename="package:///rmdx8v3.stl"/>
</geometry>
<material name="rmdx8v3_material">
<color rgba="0.26274509803921569651 0.28235294117647058432 0.30196078431372547213 1.0"/>
</material>
</visual>
<collision>
<origin xyz="-3.1225022567582527699e-17 -0.016999999999999994282 -0.05999999999999999778" rpy="1.570796326794896558 0.3141592653589793116 -3.141592653589793116" />
<geometry>
<mesh filename="package:///rmdx8v3.stl"/>
</geometry>
</collision>
<visual>
<origin xyz="-3.1225022567582527699e-17 -0.016999999999999994282 -0.05999999999999999778" rpy="1.570796326794896558 3.8110772711717211778e-33 -2.8025969286495594657e-45" />
<geometry>
<mesh filename="package:///angle_motor_connect.stl"/>
</geometry>
<material name="angle_motor_connect_material">
<color rgba="1 0 0 1.0"/>
</material>
</visual>
<collision>
<origin xyz="-3.1225022567582527699e-17 -0.016999999999999994282 -0.05999999999999999778" rpy="1.570796326794896558 3.8110772711717211778e-33 -2.8025969286495594657e-45" />
<geometry>
<mesh filename="package:///angle_motor_connect.stl"/>
</geometry>
</collision>
<inertial>
<origin xyz="5.9444804833179338578e-05 -0.0057855661598586001146 -0.054844450125644705896" rpy="0 0 0"/>
<mass value="0.76500000000000001332" />
<inertia ixx="0.00070529619085715278617" ixy="8.1991517066869466151e-07"  ixz="-1.15861949907867339e-06" iyy="0.0010092480556627560044" iyz="9.9300977410697829927e-06" izz="0.00061029448812635514032" />
</inertial>
</link>

<link name="upperleg_sasm_3">
<visual>
<origin xyz="3.4468431686904323609e-16 -6.6613381477509392425e-16 -0.078999999999999875877" rpy="1.5707963267949121011 -8.7708493677194047434e-31 1.570796326794896558" />
<geometry>
<mesh filename="package:///61804-2rs.stl"/>
</geometry>
<material name="61804-2rs_material">
<color rgba="0.61568627450980395466 0.81176470588235294379 0.92941176470588238168 1.0"/>
</material>
</visual>
<collision>
<origin xyz="3.4468431686904323609e-16 -6.6613381477509392425e-16 -0.078999999999999875877" rpy="1.5707963267949121011 -8.7708493677194047434e-31 1.570796326794896558" />
<geometry>
<mesh filename="package:///61804-2rs.stl"/>
</geometry>
</collision>
<visual>
<origin xyz="3.9443045261050590271e-31 0 -0.023000000000000020428" rpy="1.570796326794896558 1.12266282378325968e-31 -1.5869662741828017458e-31" />
<geometry>
<mesh filename="package:///inline_connect.stl"/>
</geometry>
<material name="inline_connect_material">
<color rgba="1 0 0 1.0"/>
</material>
</visual>
<collision>
<origin xyz="3.9443045261050590271e-31 0 -0.023000000000000020428" rpy="1.570796326794896558 1.12266282378325968e-31 -1.5869662741828017458e-31" />
<geometry>
<mesh filename="package:///inline_connect.stl"/>
</geometry>
</collision>
<visual>
<origin xyz="-1.6516246738967529295e-16 -4.4408920985006261617e-16 -0.053500000000000019762" rpy="-3.1415926535897900074 -4.9960036108130584926e-15 6.4739880123452744713e-15" />
<geometry>
<mesh filename="package:///upperleg_cover.stl"/>
</geometry>
<material name="upperleg_cover_material">
<color rgba="1 0 0 1.0"/>
</material>
</visual>
<collision>
<origin xyz="-1.6516246738967529295e-16 -4.4408920985006261617e-16 -0.053500000000000019762" rpy="-3.1415926535897900074 -4.9960036108130584926e-15 6.4739880123452744713e-15" />
<geometry>
<mesh filename="package:///upperleg_cover.stl"/>
</geometry>
</collision>
<visual>
<origin xyz="9.4506055723547158392e-16 -4.4408920985006261617e-16 -0.053500000000000019762" rpy="-3.1415926535897908956 -4.9960036108130584926e-15 6.4739880123452784156e-15" />
<geometry>
<mesh filename="package:///upperleg_main.stl"/>
</geometry>
<material name="upperleg_main_material">
<color rgba="1 0 0 1.0"/>
</material>
</visual>
<collision>
<origin xyz="9.4506055723547158392e-16 -4.4408920985006261617e-16 -0.053500000000000019762" rpy="-3.1415926535897908956 -4.9960036108130584926e-15 6.4739880123452784156e-15" />
<geometry>
<mesh filename="package:///upperleg_main.stl"/>
</geometry>
</collision>
<visual>
<origin xyz="3.4694469519535698154e-16 -3.3306690738754696213e-16 -0.023000000000000228595" rpy="3.141592653589788231 -2.454806747213854959e-30 1.570796326794896558" />
<geometry>
<mesh filename="package:///rmdx8v3.stl"/>
</geometry>
<material name="rmdx8v3_material">
<color rgba="0.26274509803921569651 0.28235294117647058432 0.30196078431372547213 1.0"/>
</material>
</visual>
<collision>
<origin xyz="3.4694469519535698154e-16 -3.3306690738754696213e-16 -0.023000000000000228595" rpy="3.141592653589788231 -2.454806747213854959e-30 1.570796326794896558" />
<geometry>
<mesh filename="package:///rmdx8v3.stl"/>
</geometry>
</collision>
<visual>
<origin xyz="3.4387796306280250907e-16 -5.273559366969493567e-16 -0.056000000000000021982" rpy="3.141592653589788231 -2.454806747213854959e-30 1.570796326794896558" />
<geometry>
<mesh filename="package:///motor_pulley.stl"/>
</geometry>
<material name="motor_pulley_material">
<color rgba="1 0 0 1.0"/>
</material>
</visual>
<collision>
<origin xyz="3.4387796306280250907e-16 -5.273559366969493567e-16 -0.056000000000000021982" rpy="3.141592653589788231 -2.454806747213854959e-30 1.570796326794896558" />
<geometry>
<mesh filename="package:///motor_pulley.stl"/>
</geometry>
</collision>
<inertial>
<origin xyz="0.015167598538526149907 -1.5067296746087105148e-07 -0.041111839365210629815" rpy="0 0 0"/>
<mass value="0.90300000000000013589" />
<inertia ixx="0.00079492894334645984242" ixy="2.0274701400511623129e-08"  ixz="0.00039814748290455451423" iyy="0.0027036181954660028388" iyz="-3.6423891307210346499e-09" izz="0.0028329445625492714889" />
</inertial>
</link>

<link name="lowerleg_sasm_3">
<visual>
<origin xyz="0 0 0" rpy="4.9814313621759780659e-33 -1.354866199554786051e-30 -1.1832913578315905756e-30" />
<geometry>
<mesh filename="package:///lower_leg.stl"/>
</geometry>
<material name="lower_leg_material">
<color rgba="1 0 0 1.0"/>
</material>
</visual>
<collision>
<origin xyz="0 0 0" rpy="4.9814313621759780659e-33 -1.354866199554786051e-30 -1.1832913578315905756e-30" />
<geometry>
<mesh filename="package:///lower_leg.stl"/>
</geometry>
</collision>
<visual>
<origin xyz="0 -2.7755575615628913511e-17 -0.0060000000000000053291" rpy="-1.57079632679489678 -2.0665654347996242627e-30 3.1554436208763968327e-30" />
<geometry>
<mesh filename="package:///61804-2rs.stl"/>
</geometry>
<material name="61804-2rs_material">
<color rgba="0.61568627450980395466 0.81176470588235294379 0.92941176470588238168 1.0"/>
</material>
</visual>
<collision>
<origin xyz="0 -2.7755575615628913511e-17 -0.0060000000000000053291" rpy="-1.57079632679489678 -2.0665654347996242627e-30 3.1554436208763968327e-30" />
<geometry>
<mesh filename="package:///61804-2rs.stl"/>
</geometry>
</collision>
<visual>
<origin xyz="5.8286708792820718372e-15 0 0" rpy="2.7224149397708268096e-14 1.9911547907015339569e-29 -3.7470892997911985999e-30" />
<geometry>
<mesh filename="package:///foot_ball.stl"/>
</geometry>
<material name="foot_ball_material">
<color rgba="0.26274509803921569651 0.28235294117647058432 0.30196078431372547213 1.0"/>
</material>
</visual>
<collision>
<origin xyz="5.8286708792820718372e-15 0 0" rpy="2.7224149397708268096e-14 1.9911547907015339569e-29 -3.7470892997911985999e-30" />
<geometry>
<mesh filename="package:///foot_ball.stl"/>
</geometry>
</collision>
<visual>
<origin xyz="0 0 0.0059999999999999220623" rpy="1.5707963267948961139 -8.0213613529163596808e-14 1.0255191767873004933e-29" />
<geometry>
<mesh filename="package:///61804-2rs.stl"/>
</geometry>
<material name="61804-2rs_material">
<color rgba="0.61568627450980395466 0.81176470588235294379 0.92941176470588238168 1.0"/>
</material>
</visual>
<collision>
<origin xyz="0 0 0.0059999999999999220623" rpy="1.5707963267948961139 -8.0213613529163596808e-14 1.0255191767873004933e-29" />
<geometry>
<mesh filename="package:///61804-2rs.stl"/>
</geometry>
</collision>
<inertial>
<origin xyz="0.092866734428134797841 3.406165920425646523e-09 -1.3731468338522461855e-09" rpy="0 0 0"/>
<mass value="0.13200000000000006173" />
<inertia ixx="1.7231392269124465251e-05" ixy="2.7776605628875161255e-11"  ixz="-1.1254075338876451742e-11" iyy="0.0009778131595366210127" iyz="-2.3904249350346677614e-11" izz="0.00098262259218384671693" />
</inertial>
</link>

<link name="HL_foot">
<inertial>
<origin xyz="0 0 0" rpy="0 0 0" />
<mass value="1e-9" />
<inertia ixx="0" ixy="0" ixz="0" iyy="0" iyz="0" izz="0" />
</inertial>
</link>
<joint name="HL_foot_frame" type="fixed">
<origin xyz="0.21732050807564634587 -2.7339241981394479808e-14 -5.5511151231257827021e-17" rpy="-1.57079632679489678 -2.7224149397708416402e-14 1.5707963267948661379" />
<parent link="lowerleg_sasm_3" />
<child link="HL_foot" />
<axis xyz="0 0 0"/>
</joint>

<joint name="HL2" type="revolute">
<origin xyz="0.21300000000000055 7.2719608112947753398e-15 -0.06849999999999886735" rpy="2.2204460491921242353e-16 -2.5540850755104416721e-14 6.4385996534355664365e-14" />
<parent link="upperleg_sasm_3" />
<child link="lowerleg_sasm_3" />
<axis xyz="0 0 1"/>
<limit effort="9" velocity="20" lower="-2.356194490192344837" upper="2.356194490192344837"/>
<joint_properties friction="0.0"/>
</joint>

<joint name="HL1" type="revolute">
<origin xyz="-3.0418668761338497323e-17 0.015999999999999986455 -0.05999999999999999778" rpy="1.570796326794896558 2.2747394953037020346e-15 3.2209162361520329144e-15" />
<parent link="helbow_sasm_3" />
<child link="upperleg_sasm_3" />
<axis xyz="0 0 1"/>
<limit effort="9" velocity="20" lower="-1.570796326794896558" upper="1.570796326794896558"/>
<joint_properties friction="0.0"/>
</joint>

<joint name="HL0" type="revolute">
<origin xyz="-0.16099999999999917155 0.060000000000000011657 -1.9408453586391257677e-16" rpy="-4.6713694273552509586e-30 1.570796326794896558 0" />
<parent link="body_sasm" />
<child link="helbow_sasm_3" />
<axis xyz="0 0 1"/>
<limit effort="9" velocity="20" lower="-0.785398163397448279" upper="0.785398163397448279"/>
<joint_properties friction="0.0"/>
</joint>

<link name="helbow_sasm_4">
<visual>
<origin xyz="-3.1225022567582527699e-17 -0.017000000000000001221 -0.05999999999999999778" rpy="1.570796326794896558 -0 0" />
<geometry>
<mesh filename="package:///angle_motor_connect.stl"/>
</geometry>
<material name="angle_motor_connect_material">
<color rgba="1 0 0 1.0"/>
</material>
</visual>
<collision>
<origin xyz="-3.1225022567582527699e-17 -0.017000000000000001221 -0.05999999999999999778" rpy="1.570796326794896558 -0 0" />
<geometry>
<mesh filename="package:///angle_motor_connect.stl"/>
</geometry>
</collision>
<visual>
<origin xyz="-3.1225022567582527699e-17 -0.017000000000000001221 -0.05999999999999999778" rpy="1.570796326794896558 0.3141592653589793116 3.1415926535897922278" />
<geometry>
<mesh filename="package:///rmdx8v3.stl"/>
</geometry>
<material name="rmdx8v3_material">
<color rgba="0.26274509803921569651 0.28235294117647058432 0.30196078431372547213 1.0"/>
</material>
</visual>
<collision>
<origin xyz="-3.1225022567582527699e-17 -0.017000000000000001221 -0.05999999999999999778" rpy="1.570796326794896558 0.3141592653589793116 3.1415926535897922278" />
<geometry>
<mesh filename="package:///rmdx8v3.stl"/>
</geometry>
</collision>
<inertial>
<origin xyz="5.9444804833178145956e-05 -0.005785566159858500368 -0.054844450125644705896" rpy="0 0 0"/>
<mass value="0.76500000000000001332" />
<inertia ixx="0.00070529619085715885771" ixy="8.1991517066800274147e-07"  ixz="-1.1586194990787583051e-06" iyy="0.0010092480556627703159" iyz="9.930097741070201427e-06" izz="0.00061029448812635524874" />
</inertial>
</link>

<link name="upperleg_sasm_4">
<visual>
<origin xyz="-1.108954990749267871e-17 -2.7755575615628913511e-17 0.079000000000000333844" rpy="-1.570796326794896558 2.6499421621824799184e-30 -1.570796326794896558" />
<geometry>
<mesh filename="package:///61804-2rs.stl"/>
</geometry>
<material name="61804-2rs_material">
<color rgba="0.61568627450980395466 0.81176470588235294379 0.92941176470588238168 1.0"/>
</material>
</visual>
<collision>
<origin xyz="-1.108954990749267871e-17 -2.7755575615628913511e-17 0.079000000000000333844" rpy="-1.570796326794896558 2.6499421621824799184e-30 -1.570796326794896558" />
<geometry>
<mesh filename="package:///61804-2rs.stl"/>
</geometry>
</collision>
<visual>
<origin xyz="1.3877787807816034477e-17 -2.7755575615628913511e-17 0.023000000000000020428" rpy="-2.2204460492474472971e-16 8.3815096766793541436e-30 -1.570796326794896558" />
<geometry>
<mesh filename="package:///rmdx8v3.stl"/>
</geometry>
<material name="rmdx8v3_material">
<color rgba="0.26274509803921569651 0.28235294117647058432 0.30196078431372547213 1.0"/>
</material>
</visual>
<collision>
<origin xyz="1.3877787807816034477e-17 -2.7755575615628913511e-17 0.023000000000000020428" rpy="-2.2204460492474472971e-16 8.3815096766793541436e-30 -1.570796326794896558" />
<geometry>
<mesh filename="package:///rmdx8v3.stl"/>
</geometry>
</collision>
<visual>
<origin xyz="2.2335275568130866206e-17 -2.7755575615628913511e-17 0.053500000000000005884" rpy="-1.1102230246304645882e-16 1.1102230246208832562e-16 2.0912209559343255345e-28" />
<geometry>
<mesh filename="package:///upperleg_main.stl"/>
</geometry>
<material name="upperleg_main_material">
<color rgba="1 0 0 1.0"/>
</material>
</visual>
<collision>
<origin xyz="2.2335275568130866206e-17 -2.7755575615628913511e-17 0.053500000000000005884" rpy="-1.1102230246304645882e-16 1.1102230246208832562e-16 2.0912209559343255345e-28" />
<geometry>
<mesh filename="package:///upperleg_main.stl"/>
</geometry>
</collision>
<visual>
<origin xyz="8.4574877603164094509e-18 -2.7755575615628913511e-17 0.053500000000000005884" rpy="-1.1102230246272406123e-16 1.110223024626815367e-16 -3.610542407486705846e-27" />
<geometry>
<mesh filename="package:///upperleg_cover.stl"/>
</geometry>
<material name="upperleg_cover_material">
<color rgba="1 0 0 1.0"/>
</material>
</visual>
<collision>
<origin xyz="8.4574877603164094509e-18 -2.7755575615628913511e-17 0.053500000000000005884" rpy="-1.1102230246272406123e-16 1.110223024626815367e-16 -3.610542407486705846e-27" />
<geometry>
<mesh filename="package:///upperleg_cover.stl"/>
</geometry>
</collision>
<visual>
<origin xyz="0 0 0.02300000000000000655" rpy="-1.570796326794896558 3.6620779973816428862e-30 1.479114197289388377e-31" />
<geometry>
<mesh filename="package:///inline_connect.stl"/>
</geometry>
<material name="inline_connect_material">
<color rgba="1 0 0 1.0"/>
</material>
</visual>
<collision>
<origin xyz="0 0 0.02300000000000000655" rpy="-1.570796326794896558 3.6620779973816428862e-30 1.479114197289388377e-31" />
<geometry>
<mesh filename="package:///inline_connect.stl"/>
</geometry>
</collision>
<visual>
<origin xyz="1.6430687626724614809e-18 -2.7755575615628913511e-17 0.056000000000000008105" rpy="-1.6535384173010603369e-14 1.5210055437364344837e-14 -1.570796326794896558" />
<geometry>
<mesh filename="package:///motor_pulley.stl"/>
</geometry>
<material name="motor_pulley_material">
<color rgba="1 0 0 1.0"/>
</material>
</visual>
<collision>
<origin xyz="1.6430687626724614809e-18 -2.7755575615628913511e-17 0.056000000000000008105" rpy="-1.6535384173010603369e-14 1.5210055437364344837e-14 -1.570796326794896558" />
<geometry>
<mesh filename="package:///motor_pulley.stl"/>
</geometry>
</collision>
<inertial>
<origin xyz="0.015167598538525764798 1.5067296711786132725e-07 0.041111839365210615937" rpy="0 0 0"/>
<mass value="0.90300000000000013589" />
<inertia ixx="0.00079492894334647404547" ixy="-2.0274701385221225902e-08"  ixz="-0.00039814748290456638624" iyy="0.0027036181954660119461" iyz="-3.6423891448752720087e-09" izz="0.0028329445625492797288" />
</inertial>
</link>

<link name="lowerleg_sasm_4">
<visual>
<origin xyz="0 0 0.0060000000000000330846" rpy="1.570796326794896558 1.1102230246494793408e-16 -1.6042472583800794153e-27" />
<geometry>
<mesh filename="package:///61804-2rs.stl"/>
</geometry>
<material name="61804-2rs_material">
<color rgba="0.61568627450980395466 0.81176470588235294379 0.92941176470588238168 1.0"/>
</material>
</visual>
<collision>
<origin xyz="0 0 0.0060000000000000330846" rpy="1.570796326794896558 1.1102230246494793408e-16 -1.6042472583800794153e-27" />
<geometry>
<mesh filename="package:///61804-2rs.stl"/>
</geometry>
</collision>
<visual>
<origin xyz="-5.5511151231257827021e-17 0 5.5511151231257827021e-17" rpy="3.141592653589793116 2.2204460492529631605e-16 -6.310887241768093042e-30" />
<geometry>
<mesh filename="package:///foot_ball.stl"/>
</geometry>
<material name="foot_ball_material">
<color rgba="0.26274509803921569651 0.28235294117647058432 0.30196078431372547213 1.0"/>
</material>
</visual>
<collision>
<origin xyz="-5.5511151231257827021e-17 0 5.5511151231257827021e-17" rpy="3.141592653589793116 2.2204460492529631605e-16 -6.310887241768093042e-30" />
<geometry>
<mesh filename="package:///foot_ball.stl"/>
</geometry>
</collision>
<visual>
<origin xyz="-2.7755575615628913511e-17 0 0" rpy="3.141592653589793116 2.7081386121130422452e-29 6.9518367272601623313e-30" />
<geometry>
<mesh filename="package:///lower_leg.stl"/>
</geometry>
<material name="lower_leg_material">
<color rgba="1 0 0 1.0"/>
</material>
</visual>
<collision>
<origin xyz="-2.7755575615628913511e-17 0 0" rpy="3.141592653589793116 2.7081386121130422452e-29 6.9518367272601623313e-30" />
<geometry>
<mesh filename="package:///lower_leg.stl"/>
</geometry>
</collision>
<visual>
<origin xyz="-2.7755575615628913511e-17 0 -0.0060000000000000053291" rpy="-1.57079632679489678 1.6297448791652292256e-29 7.5927862127522330219e-30" />
<geometry>
<mesh filename="package:///61804-2rs.stl"/>
</geometry>
<material name="61804-2rs_material">
<color rgba="0.61568627450980395466 0.81176470588235294379 0.92941176470588238168 1.0"/>
</material>
</visual>
<collision>
<origin xyz="-2.7755575615628913511e-17 0 -0.0060000000000000053291" rpy="-1.57079632679489678 1.6297448791652292256e-29 7.5927862127522330219e-30" />
<geometry>
<mesh filename="package:///61804-2rs.stl"/>
</geometry>
</collision>
<inertial>
<origin xyz="0.092866734428134797841 -3.4061659242104978561e-09 1.3731468274866653739e-09" rpy="0 0 0"/>
<mass value="0.13200000000000006173" />
<inertia ixx="1.7231392269124638046e-05" ixy="-2.777660555599496582e-11"  ixz="1.1254075467625459725e-11" iyy="0.00097781315953662144638" iyz="-2.390424945631128643e-11" izz="0.00098262259218384736745" />
</inertial>
</link>

<link name="HR_foot">
<inertial>
<origin xyz="0 0 0" rpy="0 0 0" />
<mass value="1e-9" />
<inertia ixx="0" ixy="0" ixz="0" iyy="0" iyz="0" izz="0" />
</inertial>
</link>
<joint name="HR_foot_frame" type="fixed">
<origin xyz="0.21732050807564637362 2.7283730830163221981e-14 0" rpy="-1.570796326794896558 2.2204460492510886297e-16 1.57079632679489678" />
<parent link="lowerleg_sasm_4" />
<child link="HR_foot" />
<axis xyz="0 0 0"/>
</joint>

<joint name="HR2" type="revolute">
<origin xyz="0.21300000000000002265 -6.467049118441536848e-15 0.068499999999999963696" rpy="1.1102230246387924942e-16 6.1232339957382020092e-17 -4.4630965589931286614e-14" />
<parent link="upperleg_sasm_4" />
<child link="lowerleg_sasm_4" />
<axis xyz="0 0 1"/>
<limit effort="9" velocity="20" lower="-2.356194490192344837" upper="2.356194490192344837"/>
<joint_properties friction="0.0"/>
</joint>

<joint name="HR1" type="revolute">
<origin xyz="-3.6033927686494999687e-17 0.016000000000000305644 -0.05999999999999999778" rpy="1.570796326794896558 7.3274719625260410554e-15 -3.141592653589793116" />
<parent link="helbow_sasm_4" />
<child link="upperleg_sasm_4" />
<axis xyz="0 0 1"/>
<limit effort="9" velocity="20" lower="-1.570796326794896558" upper="1.570796326794896558"/>
<joint_properties friction="0.0"/>
</joint>

<joint name="HR0" type="revolute">
<origin xyz="-0.16099999999999917155 -0.059999999999999983902 -1.9781398741257412101e-16" rpy="-3.141592653589793116 -1.5707963267947993025 0" />
<parent link="body_sasm" />
<child link="helbow_sasm_4" />
<axis xyz="0 0 1"/>
<limit effort="9" velocity="20" lower="-0.785398163397448279" upper="0.785398163397448279"/>
<joint_properties friction="0.0"/>
</joint>


</robot>
