<robot name="sassa">
<link name="body_sasm">
<visual>
<origin xyz="-1.11022e-16 6.93889e-18 9.35363e-17" rpy="-9.78434e-29 7.88861e-29 -1.5708" />
<geometry>
<mesh filename="package:///handle.stl"/>
</geometry>
<material name="handle_material">
<color rgba="1 0 0 1.0"/>
</material>
</visual>
<collision>
<origin xyz="-1.11022e-16 6.93889e-18 9.35363e-17" rpy="-9.78434e-29 7.88861e-29 -1.5708" />
<geometry>
<mesh filename="package:///handle.stl"/>
</geometry>
<material name="handle_material">
<color rgba="1 0 0 1.0"/>
</material>
</collision>
<visual>
<origin xyz="-0.128 1.04083e-17 -1.68846e-16" rpy="-1.5708 7.88861e-29 -1.5708" />
<geometry>
<mesh filename="package:///body_panel.stl"/>
</geometry>
<material name="body_panel_material">
<color rgba="1 0 0 1.0"/>
</material>
</visual>
<collision>
<origin xyz="-0.128 1.04083e-17 -1.68846e-16" rpy="-1.5708 7.88861e-29 -1.5708" />
<geometry>
<mesh filename="package:///body_panel.stl"/>
</geometry>
<material name="body_panel_material">
<color rgba="1 0 0 1.0"/>
</material>
</collision>
<visual>
<origin xyz="0.128 0.06 4.16339e-17" rpy="-1.5708 7.88861e-29 -1.5708" />
<geometry>
<mesh filename="package:///rmdx8v3.stl"/>
</geometry>
<material name="rmdx8v3_material">
<color rgba="0.262745 0.282353 0.301961 1.0"/>
</material>
</visual>
<collision>
<origin xyz="0.128 0.06 4.16339e-17" rpy="-1.5708 7.88861e-29 -1.5708" />
<geometry>
<mesh filename="package:///rmdx8v3.stl"/>
</geometry>
<material name="rmdx8v3_material">
<color rgba="0.262745 0.282353 0.301961 1.0"/>
</material>
</collision>
<visual>
<origin xyz="-0.128 0.06 -1.74051e-16" rpy="1.5708 7.88861e-29 -1.5708" />
<geometry>
<mesh filename="package:///rmdx8v3.stl"/>
</geometry>
<material name="rmdx8v3_material">
<color rgba="0.262745 0.282353 0.301961 1.0"/>
</material>
</visual>
<collision>
<origin xyz="-0.128 0.06 -1.74051e-16" rpy="1.5708 7.88861e-29 -1.5708" />
<geometry>
<mesh filename="package:///rmdx8v3.stl"/>
</geometry>
<material name="rmdx8v3_material">
<color rgba="0.262745 0.282353 0.301961 1.0"/>
</material>
</collision>
<visual>
<origin xyz="0 0 0" rpy="-1.76869e-74 7.88861e-29 -1.5708" />
<geometry>
<mesh filename="package:///body.stl"/>
</geometry>
<material name="body_material">
<color rgba="0.27451 0.27451 0.27451 1.0"/>
</material>
</visual>
<collision>
<origin xyz="0 0 0" rpy="-1.76869e-74 7.88861e-29 -1.5708" />
<geometry>
<mesh filename="package:///body.stl"/>
</geometry>
<material name="body_material">
<color rgba="0.27451 0.27451 0.27451 1.0"/>
</material>
</collision>
<visual>
<origin xyz="0.128 1.04083e-17 3.64292e-17" rpy="1.5708 7.88861e-29 -1.5708" />
<geometry>
<mesh filename="package:///body_panel.stl"/>
</geometry>
<material name="body_panel_material">
<color rgba="1 0 0 1.0"/>
</material>
</visual>
<collision>
<origin xyz="0.128 1.04083e-17 3.64292e-17" rpy="1.5708 7.88861e-29 -1.5708" />
<geometry>
<mesh filename="package:///body_panel.stl"/>
</geometry>
<material name="body_panel_material">
<color rgba="1 0 0 1.0"/>
</material>
</collision>
<visual>
<origin xyz="0.128 -0.06 4.16339e-17" rpy="-1.5708 7.88861e-29 -1.5708" />
<geometry>
<mesh filename="package:///rmdx8v3.stl"/>
</geometry>
<material name="rmdx8v3_material">
<color rgba="0.262745 0.282353 0.301961 1.0"/>
</material>
</visual>
<collision>
<origin xyz="0.128 -0.06 4.16339e-17" rpy="-1.5708 7.88861e-29 -1.5708" />
<geometry>
<mesh filename="package:///rmdx8v3.stl"/>
</geometry>
<material name="rmdx8v3_material">
<color rgba="0.262745 0.282353 0.301961 1.0"/>
</material>
</collision>
<visual>
<origin xyz="-0.128 -0.06 -1.74051e-16" rpy="1.5708 7.88861e-29 -1.5708" />
<geometry>
<mesh filename="package:///rmdx8v3.stl"/>
</geometry>
<material name="rmdx8v3_material">
<color rgba="0.262745 0.282353 0.301961 1.0"/>
</material>
</visual>
<collision>
<origin xyz="-0.128 -0.06 -1.74051e-16" rpy="1.5708 7.88861e-29 -1.5708" />
<geometry>
<mesh filename="package:///rmdx8v3.stl"/>
</geometry>
<material name="rmdx8v3_material">
<color rgba="0.262745 0.282353 0.301961 1.0"/>
</material>
</collision>
<inertial>
<origin xyz="1.28488e-08 1.83048e-06 0.000831456" rpy="0 0 0"/>
<mass value="4.41833" />
<inertia ixx="0.0207391" ixy="-1.82924e-09"  ixz="-7.00825e-05" iyy="0.0779377" iyz="-4.83915e-07" izz="0.0891183" />
</inertial>
</link>

<link name="helbow_sasm">
<visual>
<origin xyz="-3.1225e-17 -0.017 -0.06" rpy="1.5708 -6.5617e-34 6.5617e-34" />
<geometry>
<mesh filename="package:///angle_motor_connect.stl"/>
</geometry>
<material name="angle_motor_connect_material">
<color rgba="1 0 0 1.0"/>
</material>
</visual>
<collision>
<origin xyz="-3.1225e-17 -0.017 -0.06" rpy="1.5708 -6.5617e-34 6.5617e-34" />
<geometry>
<mesh filename="package:///angle_motor_connect.stl"/>
</geometry>
<material name="angle_motor_connect_material">
<color rgba="1 0 0 1.0"/>
</material>
</collision>
<visual>
<origin xyz="-3.02979e-17 -0.017 -0.06" rpy="1.5708 0.314159 -3.14159" />
<geometry>
<mesh filename="package:///rmdx8v3.stl"/>
</geometry>
<material name="rmdx8v3_material">
<color rgba="0.262745 0.282353 0.301961 1.0"/>
</material>
</visual>
<collision>
<origin xyz="-3.02979e-17 -0.017 -0.06" rpy="1.5708 0.314159 -3.14159" />
<geometry>
<mesh filename="package:///rmdx8v3.stl"/>
</geometry>
<material name="rmdx8v3_material">
<color rgba="0.262745 0.282353 0.301961 1.0"/>
</material>
</collision>
<inertial>
<origin xyz="6.68834e-05 -0.00652633 -0.0502736" rpy="0 0 0"/>
<mass value="1.00534" />
<inertia ixx="0.00112124" ixy="-9.11961e-05"  ixz="6.45426e-08" iyy="0.00145581" iyz="1.93651e-05" izz="0.000902064" />
</inertial>
</link>

<link name="upperleg_sasm">
<visual>
<origin xyz="7.62902e-18 0 -0.079" rpy="1.5708 2.90448e-16 1.5708" />
<geometry>
<mesh filename="package:///61804-2rs.stl"/>
</geometry>
<material name="61804-2rs_material">
<color rgba="0.615686 0.811765 0.929412 1.0"/>
</material>
</visual>
<collision>
<origin xyz="7.62902e-18 0 -0.079" rpy="1.5708 2.90448e-16 1.5708" />
<geometry>
<mesh filename="package:///61804-2rs.stl"/>
</geometry>
<material name="61804-2rs_material">
<color rgba="0.615686 0.811765 0.929412 1.0"/>
</material>
</collision>
<visual>
<origin xyz="1.66533e-16 0 -0.0535" rpy="3.14159 1.00479e-16 1.65781e-29" />
<geometry>
<mesh filename="package:///upperleg_cover.stl"/>
</geometry>
<material name="upperleg_cover_material">
<color rgba="1 0 0 1.0"/>
</material>
</visual>
<collision>
<origin xyz="1.66533e-16 0 -0.0535" rpy="3.14159 1.00479e-16 1.65781e-29" />
<geometry>
<mesh filename="package:///upperleg_cover.stl"/>
</geometry>
<material name="upperleg_cover_material">
<color rgba="1 0 0 1.0"/>
</material>
</collision>
<visual>
<origin xyz="-6.16298e-33 0 -0.023" rpy="1.5708 -0 0" />
<geometry>
<mesh filename="package:///inline_connect.stl"/>
</geometry>
<material name="inline_connect_material">
<color rgba="1 0 0 1.0"/>
</material>
</visual>
<collision>
<origin xyz="-6.16298e-33 0 -0.023" rpy="1.5708 -0 0" />
<geometry>
<mesh filename="package:///inline_connect.stl"/>
</geometry>
<material name="inline_connect_material">
<color rgba="1 0 0 1.0"/>
</material>
</collision>
<visual>
<origin xyz="6.90828e-18 0 -0.056" rpy="-3.14159 6.84039e-17 1.5708" />
<geometry>
<mesh filename="package:///motor_pulley.stl"/>
</geometry>
<material name="motor_pulley_material">
<color rgba="1 0 0 1.0"/>
</material>
</visual>
<collision>
<origin xyz="6.90828e-18 0 -0.056" rpy="-3.14159 6.84039e-17 1.5708" />
<geometry>
<mesh filename="package:///motor_pulley.stl"/>
</geometry>
<material name="motor_pulley_material">
<color rgba="1 0 0 1.0"/>
</material>
</collision>
<visual>
<origin xyz="6.93889e-18 0 -0.023" rpy="-3.14159 6.84039e-17 1.5708" />
<geometry>
<mesh filename="package:///rmdx8v3.stl"/>
</geometry>
<material name="rmdx8v3_material">
<color rgba="0.262745 0.282353 0.301961 1.0"/>
</material>
</visual>
<collision>
<origin xyz="6.93889e-18 0 -0.023" rpy="-3.14159 6.84039e-17 1.5708" />
<geometry>
<mesh filename="package:///rmdx8v3.stl"/>
</geometry>
<material name="rmdx8v3_material">
<color rgba="0.262745 0.282353 0.301961 1.0"/>
</material>
</collision>
<visual>
<origin xyz="2.77556e-17 0 -0.0535" rpy="-3.14159 3.44807e-16 1.65661e-29" />
<geometry>
<mesh filename="package:///upperleg_main.stl"/>
</geometry>
<material name="upperleg_main_material">
<color rgba="1 0 0 1.0"/>
</material>
</visual>
<collision>
<origin xyz="2.77556e-17 0 -0.0535" rpy="-3.14159 3.44807e-16 1.65661e-29" />
<geometry>
<mesh filename="package:///upperleg_main.stl"/>
</geometry>
<material name="upperleg_main_material">
<color rgba="1 0 0 1.0"/>
</material>
</collision>
<inertial>
<origin xyz="0.0174742 -1.8274e-07 -0.041935" rpy="0 0 0"/>
<mass value="1.09837" />
<inertia ixx="0.000995332" ixy="2.94361e-08"  ixz="0.000533474" iyy="0.0036193" iyz="-5.22768e-09" izz="0.00374089" />
</inertial>
</link>

<link name="lowerleg_sasm">
<visual>
<origin xyz="2.77556e-17 0 -2.77556e-17" rpy="2.93309e-32 5.29198e-31 -8.99025e-32" />
<geometry>
<mesh filename="package:///lower_leg.stl"/>
</geometry>
<material name="lower_leg_material">
<color rgba="1 0 0 1.0"/>
</material>
</visual>
<collision>
<origin xyz="2.77556e-17 0 -2.77556e-17" rpy="2.93309e-32 5.29198e-31 -8.99025e-32" />
<geometry>
<mesh filename="package:///lower_leg.stl"/>
</geometry>
<material name="lower_leg_material">
<color rgba="1 0 0 1.0"/>
</material>
</collision>
<visual>
<origin xyz="2.77556e-17 0 -0.006" rpy="-1.5708 1.56942e-15 1.03308e-30" />
<geometry>
<mesh filename="package:///61804-2rs.stl"/>
</geometry>
<material name="61804-2rs_material">
<color rgba="0.615686 0.811765 0.929412 1.0"/>
</material>
</visual>
<collision>
<origin xyz="2.77556e-17 0 -0.006" rpy="-1.5708 1.56942e-15 1.03308e-30" />
<geometry>
<mesh filename="package:///61804-2rs.stl"/>
</geometry>
<material name="61804-2rs_material">
<color rgba="0.615686 0.811765 0.929412 1.0"/>
</material>
</collision>
<visual>
<origin xyz="5.55112e-17 0 0.006" rpy="1.5708 3.26306e-15 -4.49513e-32" />
<geometry>
<mesh filename="package:///61804-2rs.stl"/>
</geometry>
<material name="61804-2rs_material">
<color rgba="0.615686 0.811765 0.929412 1.0"/>
</material>
</visual>
<collision>
<origin xyz="5.55112e-17 0 0.006" rpy="1.5708 3.26306e-15 -4.49513e-32" />
<geometry>
<mesh filename="package:///61804-2rs.stl"/>
</geometry>
<material name="61804-2rs_material">
<color rgba="0.615686 0.811765 0.929412 1.0"/>
</material>
</collision>
<visual>
<origin xyz="-1.41553e-15 0 3.33067e-16" rpy="-2.58273e-15 1.56942e-15 1.03308e-30" />
<geometry>
<mesh filename="package:///foot_ball.stl"/>
</geometry>
<material name="foot_ball_material">
<color rgba="0.262745 0.282353 0.301961 1.0"/>
</material>
</visual>
<collision>
<origin xyz="-1.41553e-15 0 3.33067e-16" rpy="-2.58273e-15 1.56942e-15 1.03308e-30" />
<geometry>
<mesh filename="package:///foot_ball.stl"/>
</geometry>
<material name="foot_ball_material">
<color rgba="0.262745 0.282353 0.301961 1.0"/>
</material>
</collision>
<inertial>
<origin xyz="0.088427 3.28077e-09 -1.32259e-09" rpy="0 0 0"/>
<mass value="0.171662" />
<inertia ixx="2.23738e-05" ixy="3.22923e-11"  ixz="-1.30887e-11" iyy="0.00127117" iyz="-2.99422e-11" izz="0.00127754" />
</inertial>
</link>

<joint name="FL2" type="revolute">
<origin xyz="0.213 6.41154e-15 -0.0685" rpy="5.37991e-16 -2.21964e-15 -1.16006e-15" />
<parent link="upperleg_sasm" />
<child link="lowerleg_sasm" />
<axis xyz="0 0 1"/>
<limit effort="1" velocity="20" lower="-2.35619" upper="2.35619"/>
<joint_properties friction="0.0"/>
</joint>

<joint name="FL1" type="revolute">
<origin xyz="-3.06858e-17 0.016 -0.06" rpy="-1.5708 -1.40252e-27 -3.14159" />
<parent link="helbow_sasm" />
<child link="upperleg_sasm" />
<axis xyz="0 0 1"/>
<limit effort="1" velocity="20" lower="-1.5708" upper="1.5708"/>
<joint_properties friction="0.0"/>
</joint>

<joint name="FL0" type="revolute">
<origin xyz="0.161 0.06 4.03787e-17" rpy="-3.12787e-30 -1.5708 0" />
<parent link="body_sasm" />
<child link="helbow_sasm" />
<axis xyz="0 0 1"/>
<limit effort="1" velocity="20" lower="-0.785398" upper="0.785398"/>
<joint_properties friction="0.0"/>
</joint>

<link name="helbow_sasm_2">
<visual>
<origin xyz="-3.1225e-17 -0.017 -0.06" rpy="1.5708 -1.23041e-32 2.18549e-35" />
<geometry>
<mesh filename="package:///angle_motor_connect.stl"/>
</geometry>
<material name="angle_motor_connect_material">
<color rgba="1 0 0 1.0"/>
</material>
</visual>
<collision>
<origin xyz="-3.1225e-17 -0.017 -0.06" rpy="1.5708 -1.23041e-32 2.18549e-35" />
<geometry>
<mesh filename="package:///angle_motor_connect.stl"/>
</geometry>
<material name="angle_motor_connect_material">
<color rgba="1 0 0 1.0"/>
</material>
</collision>
<visual>
<origin xyz="-3.02979e-17 -0.017 -0.06" rpy="1.5708 0.314159 3.14159" />
<geometry>
<mesh filename="package:///rmdx8v3.stl"/>
</geometry>
<material name="rmdx8v3_material">
<color rgba="0.262745 0.282353 0.301961 1.0"/>
</material>
</visual>
<collision>
<origin xyz="-3.02979e-17 -0.017 -0.06" rpy="1.5708 0.314159 3.14159" />
<geometry>
<mesh filename="package:///rmdx8v3.stl"/>
</geometry>
<material name="rmdx8v3_material">
<color rgba="0.262745 0.282353 0.301961 1.0"/>
</material>
</collision>
<inertial>
<origin xyz="6.68834e-05 -0.00652633 -0.0502736" rpy="0 0 0"/>
<mass value="1.00534" />
<inertia ixx="0.00112124" ixy="-9.11961e-05"  ixz="6.45426e-08" iyy="0.00145581" iyz="1.93651e-05" izz="0.000902064" />
</inertial>
</link>

<link name="upperleg_sasm_2">
<visual>
<origin xyz="-2.46519e-32 2.77556e-17 -0.023" rpy="1.5708 -0 0" />
<geometry>
<mesh filename="package:///inline_connect.stl"/>
</geometry>
<material name="inline_connect_material">
<color rgba="1 0 0 1.0"/>
</material>
</visual>
<collision>
<origin xyz="-2.46519e-32 2.77556e-17 -0.023" rpy="1.5708 -0 0" />
<geometry>
<mesh filename="package:///inline_connect.stl"/>
</geometry>
<material name="inline_connect_material">
<color rgba="1 0 0 1.0"/>
</material>
</collision>
<visual>
<origin xyz="6.31402e-17 5.82867e-16 -0.079" rpy="1.5708 -6.70276e-15 1.5708" />
<geometry>
<mesh filename="package:///61804-2rs.stl"/>
</geometry>
<material name="61804-2rs_material">
<color rgba="0.615686 0.811765 0.929412 1.0"/>
</material>
</visual>
<collision>
<origin xyz="6.31402e-17 5.82867e-16 -0.079" rpy="1.5708 -6.70276e-15 1.5708" />
<geometry>
<mesh filename="package:///61804-2rs.stl"/>
</geometry>
<material name="61804-2rs_material">
<color rgba="0.615686 0.811765 0.929412 1.0"/>
</material>
</collision>
<visual>
<origin xyz="6.24194e-17 6.10623e-16 -0.056" rpy="-3.14159 -6.70276e-15 1.5708" />
<geometry>
<mesh filename="package:///motor_pulley.stl"/>
</geometry>
<material name="motor_pulley_material">
<color rgba="1 0 0 1.0"/>
</material>
</visual>
<collision>
<origin xyz="6.24194e-17 6.10623e-16 -0.056" rpy="-3.14159 -6.70276e-15 1.5708" />
<geometry>
<mesh filename="package:///motor_pulley.stl"/>
</geometry>
<material name="motor_pulley_material">
<color rgba="1 0 0 1.0"/>
</material>
</collision>
<visual>
<origin xyz="-1.28866e-15 4.44089e-16 -0.0535" rpy="-3.14159 5.68017e-16 -7.14533e-15" />
<geometry>
<mesh filename="package:///upperleg_cover.stl"/>
</geometry>
<material name="upperleg_cover_material">
<color rgba="1 0 0 1.0"/>
</material>
</visual>
<collision>
<origin xyz="-1.28866e-15 4.44089e-16 -0.0535" rpy="-3.14159 5.68017e-16 -7.14533e-15" />
<geometry>
<mesh filename="package:///upperleg_cover.stl"/>
</geometry>
<material name="upperleg_cover_material">
<color rgba="1 0 0 1.0"/>
</material>
</collision>
<visual>
<origin xyz="1.06363e-15 4.44089e-16 -0.0535" rpy="-3.14159 5.68017e-16 -7.14533e-15" />
<geometry>
<mesh filename="package:///upperleg_main.stl"/>
</geometry>
<material name="upperleg_main_material">
<color rgba="1 0 0 1.0"/>
</material>
</visual>
<collision>
<origin xyz="1.06363e-15 4.44089e-16 -0.0535" rpy="-3.14159 5.68017e-16 -7.14533e-15" />
<geometry>
<mesh filename="package:///upperleg_main.stl"/>
</geometry>
<material name="upperleg_main_material">
<color rgba="1 0 0 1.0"/>
</material>
</collision>
<visual>
<origin xyz="6.245e-17 6.10623e-16 -0.023" rpy="-3.14159 -6.70276e-15 1.5708" />
<geometry>
<mesh filename="package:///rmdx8v3.stl"/>
</geometry>
<material name="rmdx8v3_material">
<color rgba="0.262745 0.282353 0.301961 1.0"/>
</material>
</visual>
<collision>
<origin xyz="6.245e-17 6.10623e-16 -0.023" rpy="-3.14159 -6.70276e-15 1.5708" />
<geometry>
<mesh filename="package:///rmdx8v3.stl"/>
</geometry>
<material name="rmdx8v3_material">
<color rgba="0.262745 0.282353 0.301961 1.0"/>
</material>
</collision>
<inertial>
<origin xyz="0.0174742 -1.8274e-07 -0.041935" rpy="0 0 0"/>
<mass value="1.09837" />
<inertia ixx="0.000995332" ixy="2.94361e-08"  ixz="0.000533474" iyy="0.0036193" iyz="-5.22768e-09" izz="0.00374089" />
</inertial>
</link>

<link name="lowerleg_sasm_2">
<visual>
<origin xyz="0 0 -0.006" rpy="-1.5708 -2.89216e-16 -2.543e-30" />
<geometry>
<mesh filename="package:///61804-2rs.stl"/>
</geometry>
<material name="61804-2rs_material">
<color rgba="0.615686 0.811765 0.929412 1.0"/>
</material>
</visual>
<collision>
<origin xyz="0 0 -0.006" rpy="-1.5708 -2.89216e-16 -2.543e-30" />
<geometry>
<mesh filename="package:///61804-2rs.stl"/>
</geometry>
<material name="61804-2rs_material">
<color rgba="0.615686 0.811765 0.929412 1.0"/>
</material>
</collision>
<visual>
<origin xyz="9.54792e-15 0 -5.55112e-17" rpy="-8.95446e-16 -2.89216e-16 -2.543e-30" />
<geometry>
<mesh filename="package:///foot_ball.stl"/>
</geometry>
<material name="foot_ball_material">
<color rgba="0.262745 0.282353 0.301961 1.0"/>
</material>
</visual>
<collision>
<origin xyz="9.54792e-15 0 -5.55112e-17" rpy="-8.95446e-16 -2.89216e-16 -2.543e-30" />
<geometry>
<mesh filename="package:///foot_ball.stl"/>
</geometry>
<material name="foot_ball_material">
<color rgba="0.262745 0.282353 0.301961 1.0"/>
</material>
</collision>
<visual>
<origin xyz="0 0 0" rpy="-5.10005e-33 2.30728e-32 -9.00538e-32" />
<geometry>
<mesh filename="package:///lower_leg.stl"/>
</geometry>
<material name="lower_leg_material">
<color rgba="1 0 0 1.0"/>
</material>
</visual>
<collision>
<origin xyz="0 0 0" rpy="-5.10005e-33 2.30728e-32 -9.00538e-32" />
<geometry>
<mesh filename="package:///lower_leg.stl"/>
</geometry>
<material name="lower_leg_material">
<color rgba="1 0 0 1.0"/>
</material>
</collision>
<visual>
<origin xyz="0 0 0.006" rpy="1.5708 -4.01338e-31 6.90989e-31" />
<geometry>
<mesh filename="package:///61804-2rs.stl"/>
</geometry>
<material name="61804-2rs_material">
<color rgba="0.615686 0.811765 0.929412 1.0"/>
</material>
</visual>
<collision>
<origin xyz="0 0 0.006" rpy="1.5708 -4.01338e-31 6.90989e-31" />
<geometry>
<mesh filename="package:///61804-2rs.stl"/>
</geometry>
<material name="61804-2rs_material">
<color rgba="0.615686 0.811765 0.929412 1.0"/>
</material>
</collision>
<inertial>
<origin xyz="0.088427 3.28077e-09 -1.32259e-09" rpy="0 0 0"/>
<mass value="0.171662" />
<inertia ixx="2.23738e-05" ixy="3.22923e-11"  ixz="-1.30887e-11" iyy="0.00127117" iyz="-2.99422e-11" izz="0.00127754" />
</inertial>
</link>

<joint name="FR2" type="revolute">
<origin xyz="0.213 5.35683e-15 -0.0685" rpy="-3.14159 7.90062e-16 -9.00322e-15" />
<parent link="upperleg_sasm_2" />
<child link="lowerleg_sasm_2" />
<axis xyz="0 0 1"/>
<limit effort="1" velocity="20" lower="-2.35619" upper="2.35619"/>
<joint_properties friction="0.0"/>
</joint>

<joint name="FR1" type="revolute">
<origin xyz="-4.03316e-17 0.016 -0.06" rpy="1.5708 -1.84678e-15 3.8968e-17" />
<parent link="helbow_sasm_2" />
<child link="upperleg_sasm_2" />
<axis xyz="0 0 1"/>
<limit effort="1" velocity="20" lower="-1.5708" upper="1.5708"/>
<joint_properties friction="0.0"/>
</joint>

<joint name="FR0" type="revolute">
<origin xyz="0.161 -0.06 4.03787e-17" rpy="-3.14159 1.5708 0" />
<parent link="body_sasm" />
<child link="helbow_sasm_2" />
<axis xyz="0 0 1"/>
<limit effort="1" velocity="20" lower="-0.785398" upper="0.785398"/>
<joint_properties friction="0.0"/>
</joint>

<link name="helbow_sasm_3">
<visual>
<origin xyz="-3.02979e-17 -0.017 -0.06" rpy="1.5708 0.314159 -3.14159" />
<geometry>
<mesh filename="package:///rmdx8v3.stl"/>
</geometry>
<material name="rmdx8v3_material">
<color rgba="0.262745 0.282353 0.301961 1.0"/>
</material>
</visual>
<collision>
<origin xyz="-3.02979e-17 -0.017 -0.06" rpy="1.5708 0.314159 -3.14159" />
<geometry>
<mesh filename="package:///rmdx8v3.stl"/>
</geometry>
<material name="rmdx8v3_material">
<color rgba="0.262745 0.282353 0.301961 1.0"/>
</material>
</collision>
<visual>
<origin xyz="-3.1225e-17 -0.017 -0.06" rpy="1.5708 3.81108e-33 -2.8026e-45" />
<geometry>
<mesh filename="package:///angle_motor_connect.stl"/>
</geometry>
<material name="angle_motor_connect_material">
<color rgba="1 0 0 1.0"/>
</material>
</visual>
<collision>
<origin xyz="-3.1225e-17 -0.017 -0.06" rpy="1.5708 3.81108e-33 -2.8026e-45" />
<geometry>
<mesh filename="package:///angle_motor_connect.stl"/>
</geometry>
<material name="angle_motor_connect_material">
<color rgba="1 0 0 1.0"/>
</material>
</collision>
<inertial>
<origin xyz="6.68834e-05 -0.00652633 -0.0502736" rpy="0 0 0"/>
<mass value="1.00534" />
<inertia ixx="0.00112124" ixy="-9.11961e-05"  ixz="6.45426e-08" iyy="0.00145581" iyz="1.93651e-05" izz="0.000902064" />
</inertial>
</link>

<link name="upperleg_sasm_3">
<visual>
<origin xyz="3.46125e-16 -6.66134e-16 -0.079" rpy="1.5708 -2.3069e-30 1.5708" />
<geometry>
<mesh filename="package:///61804-2rs.stl"/>
</geometry>
<material name="61804-2rs_material">
<color rgba="0.615686 0.811765 0.929412 1.0"/>
</material>
</visual>
<collision>
<origin xyz="3.46125e-16 -6.66134e-16 -0.079" rpy="1.5708 -2.3069e-30 1.5708" />
<geometry>
<mesh filename="package:///61804-2rs.stl"/>
</geometry>
<material name="61804-2rs_material">
<color rgba="0.615686 0.811765 0.929412 1.0"/>
</material>
</collision>
<visual>
<origin xyz="0 0 -0.023" rpy="1.5708 1.12266e-31 -1.58697e-31" />
<geometry>
<mesh filename="package:///inline_connect.stl"/>
</geometry>
<material name="inline_connect_material">
<color rgba="1 0 0 1.0"/>
</material>
</visual>
<collision>
<origin xyz="0 0 -0.023" rpy="1.5708 1.12266e-31 -1.58697e-31" />
<geometry>
<mesh filename="package:///inline_connect.stl"/>
</geometry>
<material name="inline_connect_material">
<color rgba="1 0 0 1.0"/>
</material>
</collision>
<visual>
<origin xyz="-1.85709e-16 -4.16334e-16 -0.0535" rpy="-3.14159 -4.996e-15 6.47399e-15" />
<geometry>
<mesh filename="package:///upperleg_cover.stl"/>
</geometry>
<material name="upperleg_cover_material">
<color rgba="1 0 0 1.0"/>
</material>
</visual>
<collision>
<origin xyz="-1.85709e-16 -4.16334e-16 -0.0535" rpy="-3.14159 -4.996e-15 6.47399e-15" />
<geometry>
<mesh filename="package:///upperleg_cover.stl"/>
</geometry>
<material name="upperleg_cover_material">
<color rgba="1 0 0 1.0"/>
</material>
</collision>
<visual>
<origin xyz="9.40141e-16 -4.71845e-16 -0.0535" rpy="-3.14159 -4.996e-15 6.47399e-15" />
<geometry>
<mesh filename="package:///upperleg_main.stl"/>
</geometry>
<material name="upperleg_main_material">
<color rgba="1 0 0 1.0"/>
</material>
</visual>
<collision>
<origin xyz="9.40141e-16 -4.71845e-16 -0.0535" rpy="-3.14159 -4.996e-15 6.47399e-15" />
<geometry>
<mesh filename="package:///upperleg_main.stl"/>
</geometry>
<material name="upperleg_main_material">
<color rgba="1 0 0 1.0"/>
</material>
</collision>
<visual>
<origin xyz="3.45435e-16 -3.33067e-16 -0.023" rpy="3.14159 -3.09576e-30 1.5708" />
<geometry>
<mesh filename="package:///rmdx8v3.stl"/>
</geometry>
<material name="rmdx8v3_material">
<color rgba="0.262745 0.282353 0.301961 1.0"/>
</material>
</visual>
<collision>
<origin xyz="3.45435e-16 -3.33067e-16 -0.023" rpy="3.14159 -3.09576e-30 1.5708" />
<geometry>
<mesh filename="package:///rmdx8v3.stl"/>
</geometry>
<material name="rmdx8v3_material">
<color rgba="0.262745 0.282353 0.301961 1.0"/>
</material>
</collision>
<visual>
<origin xyz="3.45405e-16 -5.55112e-16 -0.056" rpy="3.14159 -3.09576e-30 1.5708" />
<geometry>
<mesh filename="package:///motor_pulley.stl"/>
</geometry>
<material name="motor_pulley_material">
<color rgba="1 0 0 1.0"/>
</material>
</visual>
<collision>
<origin xyz="3.45405e-16 -5.55112e-16 -0.056" rpy="3.14159 -3.09576e-30 1.5708" />
<geometry>
<mesh filename="package:///motor_pulley.stl"/>
</geometry>
<material name="motor_pulley_material">
<color rgba="1 0 0 1.0"/>
</material>
</collision>
<inertial>
<origin xyz="0.0174742 -1.8274e-07 -0.041935" rpy="0 0 0"/>
<mass value="1.09837" />
<inertia ixx="0.000995332" ixy="2.94361e-08"  ixz="0.000533474" iyy="0.0036193" iyz="-5.22768e-09" izz="0.00374089" />
</inertial>
</link>

<link name="lowerleg_sasm_3">
<visual>
<origin xyz="0 0 0" rpy="3.50108e-31 -4.51031e-30 -1.18329e-30" />
<geometry>
<mesh filename="package:///lower_leg.stl"/>
</geometry>
<material name="lower_leg_material">
<color rgba="1 0 0 1.0"/>
</material>
</visual>
<collision>
<origin xyz="0 0 0" rpy="3.50108e-31 -4.51031e-30 -1.18329e-30" />
<geometry>
<mesh filename="package:///lower_leg.stl"/>
</geometry>
<material name="lower_leg_material">
<color rgba="1 0 0 1.0"/>
</material>
</collision>
<visual>
<origin xyz="2.77556e-17 0 -0.006" rpy="-1.5708 -5.22201e-30 3.15544e-30" />
<geometry>
<mesh filename="package:///61804-2rs.stl"/>
</geometry>
<material name="61804-2rs_material">
<color rgba="0.615686 0.811765 0.929412 1.0"/>
</material>
</visual>
<collision>
<origin xyz="2.77556e-17 0 -0.006" rpy="-1.5708 -5.22201e-30 3.15544e-30" />
<geometry>
<mesh filename="package:///61804-2rs.stl"/>
</geometry>
<material name="61804-2rs_material">
<color rgba="0.615686 0.811765 0.929412 1.0"/>
</material>
</collision>
<visual>
<origin xyz="5.82867e-15 2.77556e-17 -2.77556e-17" rpy="2.72241e-14 1.67561e-29 -3.74709e-30" />
<geometry>
<mesh filename="package:///foot_ball.stl"/>
</geometry>
<material name="foot_ball_material">
<color rgba="0.262745 0.282353 0.301961 1.0"/>
</material>
</visual>
<collision>
<origin xyz="5.82867e-15 2.77556e-17 -2.77556e-17" rpy="2.72241e-14 1.67561e-29 -3.74709e-30" />
<geometry>
<mesh filename="package:///foot_ball.stl"/>
</geometry>
<material name="foot_ball_material">
<color rgba="0.262745 0.282353 0.301961 1.0"/>
</material>
</collision>
<visual>
<origin xyz="2.77556e-17 -2.77556e-17 0.006" rpy="1.5708 -8.02136e-14 -2.33739e-27" />
<geometry>
<mesh filename="package:///61804-2rs.stl"/>
</geometry>
<material name="61804-2rs_material">
<color rgba="0.615686 0.811765 0.929412 1.0"/>
</material>
</visual>
<collision>
<origin xyz="2.77556e-17 -2.77556e-17 0.006" rpy="1.5708 -8.02136e-14 -2.33739e-27" />
<geometry>
<mesh filename="package:///61804-2rs.stl"/>
</geometry>
<material name="61804-2rs_material">
<color rgba="0.615686 0.811765 0.929412 1.0"/>
</material>
</collision>
<inertial>
<origin xyz="0.088427 3.28077e-09 -1.32259e-09" rpy="0 0 0"/>
<mass value="0.171662" />
<inertia ixx="2.23738e-05" ixy="3.22923e-11"  ixz="-1.30887e-11" iyy="0.00127117" iyz="-2.99422e-11" izz="0.00127754" />
</inertial>
</link>

<joint name="HL2" type="revolute">
<origin xyz="0.213 7.27196e-15 -0.0685" rpy="2.22045e-16 -2.55409e-14 6.4386e-14" />
<parent link="upperleg_sasm_3" />
<child link="lowerleg_sasm_3" />
<axis xyz="0 0 1"/>
<limit effort="1" velocity="20" lower="-2.35619" upper="2.35619"/>
<joint_properties friction="0.0"/>
</joint>

<joint name="HL1" type="revolute">
<origin xyz="3.01347e-18 0.016 -0.06" rpy="1.5708 2.27474e-15 3.22092e-15" />
<parent link="helbow_sasm_3" />
<child link="upperleg_sasm_3" />
<axis xyz="0 0 1"/>
<limit effort="1" velocity="20" lower="-1.5708" upper="1.5708"/>
<joint_properties friction="0.0"/>
</joint>

<joint name="HL0" type="revolute">
<origin xyz="-0.161 0.06 -1.7453e-16" rpy="-4.67137e-30 1.5708 0" />
<parent link="body_sasm" />
<child link="helbow_sasm_3" />
<axis xyz="0 0 1"/>
<limit effort="1" velocity="20" lower="-0.785398" upper="0.785398"/>
<joint_properties friction="0.0"/>
</joint>

<link name="helbow_sasm_4">
<visual>
<origin xyz="-3.1225e-17 -0.017 -0.06" rpy="1.5708 -0 0" />
<geometry>
<mesh filename="package:///angle_motor_connect.stl"/>
</geometry>
<material name="angle_motor_connect_material">
<color rgba="1 0 0 1.0"/>
</material>
</visual>
<collision>
<origin xyz="-3.1225e-17 -0.017 -0.06" rpy="1.5708 -0 0" />
<geometry>
<mesh filename="package:///angle_motor_connect.stl"/>
</geometry>
<material name="angle_motor_connect_material">
<color rgba="1 0 0 1.0"/>
</material>
</collision>
<visual>
<origin xyz="-3.02979e-17 -0.017 -0.06" rpy="1.5708 0.314159 3.14159" />
<geometry>
<mesh filename="package:///rmdx8v3.stl"/>
</geometry>
<material name="rmdx8v3_material">
<color rgba="0.262745 0.282353 0.301961 1.0"/>
</material>
</visual>
<collision>
<origin xyz="-3.02979e-17 -0.017 -0.06" rpy="1.5708 0.314159 3.14159" />
<geometry>
<mesh filename="package:///rmdx8v3.stl"/>
</geometry>
<material name="rmdx8v3_material">
<color rgba="0.262745 0.282353 0.301961 1.0"/>
</material>
</collision>
<inertial>
<origin xyz="6.68834e-05 -0.00652633 -0.0502736" rpy="0 0 0"/>
<mass value="1.00534" />
<inertia ixx="0.00112124" ixy="-9.11961e-05"  ixz="6.45426e-08" iyy="0.00145581" iyz="1.93651e-05" izz="0.000902064" />
</inertial>
</link>

<link name="upperleg_sasm_4">
<visual>
<origin xyz="7.26473e-18 0 -0.079" rpy="1.5708 -2.64994e-30 1.5708" />
<geometry>
<mesh filename="package:///61804-2rs.stl"/>
</geometry>
<material name="61804-2rs_material">
<color rgba="0.615686 0.811765 0.929412 1.0"/>
</material>
</visual>
<collision>
<origin xyz="7.26473e-18 0 -0.079" rpy="1.5708 -2.64994e-30 1.5708" />
<geometry>
<mesh filename="package:///61804-2rs.stl"/>
</geometry>
<material name="61804-2rs_material">
<color rgba="0.615686 0.811765 0.929412 1.0"/>
</material>
</collision>
<visual>
<origin xyz="6.5746e-18 2.77556e-17 -0.023" rpy="3.14159 -8.38151e-30 1.5708" />
<geometry>
<mesh filename="package:///rmdx8v3.stl"/>
</geometry>
<material name="rmdx8v3_material">
<color rgba="0.262745 0.282353 0.301961 1.0"/>
</material>
</visual>
<collision>
<origin xyz="6.5746e-18 2.77556e-17 -0.023" rpy="3.14159 -8.38151e-30 1.5708" />
<geometry>
<mesh filename="package:///rmdx8v3.stl"/>
</geometry>
<material name="rmdx8v3_material">
<color rgba="0.262745 0.282353 0.301961 1.0"/>
</material>
</collision>
<visual>
<origin xyz="1.3621e-17 5.55112e-17 -0.0535" rpy="3.14159 -1.11022e-16 -2.09122e-28" />
<geometry>
<mesh filename="package:///upperleg_main.stl"/>
</geometry>
<material name="upperleg_main_material">
<color rgba="1 0 0 1.0"/>
</material>
</visual>
<collision>
<origin xyz="1.3621e-17 5.55112e-17 -0.0535" rpy="3.14159 -1.11022e-16 -2.09122e-28" />
<geometry>
<mesh filename="package:///upperleg_main.stl"/>
</geometry>
<material name="upperleg_main_material">
<color rgba="1 0 0 1.0"/>
</material>
</collision>
<visual>
<origin xyz="-4.23273e-19 2.77556e-17 -0.0535" rpy="3.14159 -1.11022e-16 3.61054e-27" />
<geometry>
<mesh filename="package:///upperleg_cover.stl"/>
</geometry>
<material name="upperleg_cover_material">
<color rgba="1 0 0 1.0"/>
</material>
</visual>
<collision>
<origin xyz="-4.23273e-19 2.77556e-17 -0.0535" rpy="3.14159 -1.11022e-16 3.61054e-27" />
<geometry>
<mesh filename="package:///upperleg_cover.stl"/>
</geometry>
<material name="upperleg_cover_material">
<color rgba="1 0 0 1.0"/>
</material>
</collision>
<visual>
<origin xyz="-1.57772e-30 0 -0.023" rpy="1.5708 -3.66208e-30 -1.47911e-31" />
<geometry>
<mesh filename="package:///inline_connect.stl"/>
</geometry>
<material name="inline_connect_material">
<color rgba="1 0 0 1.0"/>
</material>
</visual>
<collision>
<origin xyz="-1.57772e-30 0 -0.023" rpy="1.5708 -3.66208e-30 -1.47911e-31" />
<geometry>
<mesh filename="package:///inline_connect.stl"/>
</geometry>
<material name="inline_connect_material">
<color rgba="1 0 0 1.0"/>
</material>
</collision>
<visual>
<origin xyz="6.54399e-18 2.77556e-17 -0.056" rpy="3.14159 -1.52101e-14 1.5708" />
<geometry>
<mesh filename="package:///motor_pulley.stl"/>
</geometry>
<material name="motor_pulley_material">
<color rgba="1 0 0 1.0"/>
</material>
</visual>
<collision>
<origin xyz="6.54399e-18 2.77556e-17 -0.056" rpy="3.14159 -1.52101e-14 1.5708" />
<geometry>
<mesh filename="package:///motor_pulley.stl"/>
</geometry>
<material name="motor_pulley_material">
<color rgba="1 0 0 1.0"/>
</material>
</collision>
<inertial>
<origin xyz="0.0174742 -1.8274e-07 -0.041935" rpy="0 0 0"/>
<mass value="1.09837" />
<inertia ixx="0.000995332" ixy="2.94361e-08"  ixz="0.000533474" iyy="0.0036193" iyz="-5.22768e-09" izz="0.00374089" />
</inertial>
</link>

<link name="lowerleg_sasm_4">
<visual>
<origin xyz="-2.77556e-17 0 -0.006" rpy="-1.5708 -1.11022e-16 1.60425e-27" />
<geometry>
<mesh filename="package:///61804-2rs.stl"/>
</geometry>
<material name="61804-2rs_material">
<color rgba="0.615686 0.811765 0.929412 1.0"/>
</material>
</visual>
<collision>
<origin xyz="-2.77556e-17 0 -0.006" rpy="-1.5708 -1.11022e-16 1.60425e-27" />
<geometry>
<mesh filename="package:///61804-2rs.stl"/>
</geometry>
<material name="61804-2rs_material">
<color rgba="0.615686 0.811765 0.929412 1.0"/>
</material>
</collision>
<visual>
<origin xyz="0 0 -5.55112e-17" rpy="-2.22045e-16 -2.22045e-16 6.31089e-30" />
<geometry>
<mesh filename="package:///foot_ball.stl"/>
</geometry>
<material name="foot_ball_material">
<color rgba="0.262745 0.282353 0.301961 1.0"/>
</material>
</visual>
<collision>
<origin xyz="0 0 -5.55112e-17" rpy="-2.22045e-16 -2.22045e-16 6.31089e-30" />
<geometry>
<mesh filename="package:///foot_ball.stl"/>
</geometry>
<material name="foot_ball_material">
<color rgba="0.262745 0.282353 0.301961 1.0"/>
</material>
</collision>
<visual>
<origin xyz="-2.77556e-17 0 0" rpy="-3.0662e-32 -2.70814e-29 -6.95184e-30" />
<geometry>
<mesh filename="package:///lower_leg.stl"/>
</geometry>
<material name="lower_leg_material">
<color rgba="1 0 0 1.0"/>
</material>
</visual>
<collision>
<origin xyz="-2.77556e-17 0 0" rpy="-3.0662e-32 -2.70814e-29 -6.95184e-30" />
<geometry>
<mesh filename="package:///lower_leg.stl"/>
</geometry>
<material name="lower_leg_material">
<color rgba="1 0 0 1.0"/>
</material>
</collision>
<visual>
<origin xyz="0 0 0.006" rpy="1.5708 -1.62974e-29 -7.59279e-30" />
<geometry>
<mesh filename="package:///61804-2rs.stl"/>
</geometry>
<material name="61804-2rs_material">
<color rgba="0.615686 0.811765 0.929412 1.0"/>
</material>
</visual>
<collision>
<origin xyz="0 0 0.006" rpy="1.5708 -1.62974e-29 -7.59279e-30" />
<geometry>
<mesh filename="package:///61804-2rs.stl"/>
</geometry>
<material name="61804-2rs_material">
<color rgba="0.615686 0.811765 0.929412 1.0"/>
</material>
</collision>
<inertial>
<origin xyz="0.088427 3.28077e-09 -1.32259e-09" rpy="0 0 0"/>
<mass value="0.171662" />
<inertia ixx="2.23738e-05" ixy="3.22923e-11"  ixz="-1.30887e-11" iyy="0.00127117" iyz="-2.99422e-11" izz="0.00127754" />
</inertial>
</link>

<joint name="HR2" type="revolute">
<origin xyz="0.213 6.46705e-15 -0.0685" rpy="1.11022e-16 -6.12323e-17 4.4631e-14" />
<parent link="upperleg_sasm_4" />
<child link="lowerleg_sasm_4" />
<axis xyz="0 0 1"/>
<limit effort="1" velocity="20" lower="-2.35619" upper="2.35619"/>
<joint_properties friction="0.0"/>
</joint>

<joint name="HR1" type="revolute">
<origin xyz="-3.06858e-17 0.016 -0.06" rpy="-1.5708 7.32747e-15 -3.14159" />
<parent link="helbow_sasm_4" />
<child link="upperleg_sasm_4" />
<axis xyz="0 0 1"/>
<limit effort="1" velocity="20" lower="-1.5708" upper="1.5708"/>
<joint_properties friction="0.0"/>
</joint>

<joint name="HR0" type="revolute">
<origin xyz="-0.161 -0.06 -1.7453e-16" rpy="-3.14159 -1.5708 0" />
<parent link="body_sasm" />
<child link="helbow_sasm_4" />
<axis xyz="0 0 1"/>
<limit effort="1" velocity="20" lower="-0.785398" upper="0.785398"/>
<joint_properties friction="0.0"/>
</joint>


</robot>
